<?xml version="1.0" ?>
<!-- =================================================================================== -->
<!-- |    This document was autogenerated by xacro from my_mecanum_robot.urdf.xacro    | -->
<!-- |    EDITING THIS FILE BY HAND IS NOT RECOMMENDED                                 | -->
<!-- =================================================================================== -->
<robot name="my_robot">
  <material name="blue">
    <color rgba="0 0 0.5 1"/>
  </material>
  <material name="grey">
    <color rgba="0.5 0.5 0.5 1"/>
  </material>
  <material name="orange">
    <color rgba="1.0 0.5 0 1"/>
  </material>
  <material name="yellow">
    <color rgba="1.0 1.0 0 1"/>
  </material>
  <link name="base_footprint"/>
  <!-- collision and inertia box close to floor for lateral movements -->
  <link name="base_link">
    <visual>
      <geometry>
        <box size="0.26 0.15 0.08"/>
      </geometry>
      <origin rpy="0 0 0" xyz="0 0 0.04"/>
      <material name="yellow"/>
    </visual>
    <collision>
      <geometry>
        <box size="0.26 0.15 0.08"/>
      </geometry>
      <origin rpy="0 0 0" xyz="0 0 0.0"/>
    </collision>
    <inertial>
      <origin rpy="0 0 0" xyz="0 0 0.0"/>
      <mass value="4.0"/>
      <inertia ixx="0.09866666666666668" ixy="0" ixz="0" iyy="0.12013333333333334" iyz="0" izz="0.03853333333333333"/>
    </inertial>
  </link>
  <link name="lower_right_wheel_link">
    <visual>
      <geometry>
        <cylinder length="0.02" radius="0.04"/>
        <!--<mesh filename="package://my_robot_description/meshes/left_tire.stl" scale="0.001 0.001 0.001"/>-->
      </geometry>
      <origin rpy="1.5707963267948966 0 0" xyz="0 0 0"/>
      <material name="grey"/>
    </visual>
    <collision>
      <geometry>
        <cylinder length="0.02" radius="0.04"/>
      </geometry>
      <origin rpy="1.5707963267948966 0 0" xyz="0 0 0"/>
    </collision>
    <inertial>
      <origin rpy="1.5707963267948966 0 0" xyz="0 0 0"/>
      <mass value="0.2"/>
      <inertia ixx="0.00034666666666666667" ixy="0" ixz="0" iyy="0.00034666666666666667" iyz="0" izz="0.00064"/>
    </inertial>
  </link>
  <link name="lower_left_wheel_link">
    <visual>
      <geometry>
        <cylinder length="0.02" radius="0.04"/>
        <!--<mesh filename="package://my_robot_description/meshes/left_tire.stl" scale="0.001 0.001 0.001"/>-->
      </geometry>
      <origin rpy="1.5707963267948966 0 0" xyz="0 0 0"/>
      <material name="grey"/>
    </visual>
    <collision>
      <geometry>
        <cylinder length="0.02" radius="0.04"/>
      </geometry>
      <origin rpy="1.5707963267948966 0 0" xyz="0 0 0"/>
    </collision>
    <inertial>
      <origin rpy="1.5707963267948966 0 0" xyz="0 0 0"/>
      <mass value="0.2"/>
      <inertia ixx="0.00034666666666666667" ixy="0" ixz="0" iyy="0.00034666666666666667" iyz="0" izz="0.00064"/>
    </inertial>
  </link>
  <link name="upper_right_wheel_link">
    <visual>
      <geometry>
        <cylinder length="0.02" radius="0.04"/>
        <!--<mesh filename="package://my_robot_description/meshes/left_tire.stl" scale="0.001 0.001 0.001"/>-->
      </geometry>
      <origin rpy="1.5707963267948966 0 0" xyz="0 0 0"/>
      <material name="grey"/>
    </visual>
    <collision>
      <geometry>
        <cylinder length="0.02" radius="0.04"/>
      </geometry>
      <origin rpy="1.5707963267948966 0 0" xyz="0 0 0"/>
    </collision>
    <inertial>
      <origin rpy="1.5707963267948966 0 0" xyz="0 0 0"/>
      <mass value="0.2"/>
      <inertia ixx="0.00034666666666666667" ixy="0" ixz="0" iyy="0.00034666666666666667" iyz="0" izz="0.00064"/>
    </inertial>
  </link>
  <link name="upper_left_wheel_link">
    <visual>
      <geometry>
        <cylinder length="0.02" radius="0.04"/>
        <!--<mesh filename="package://my_robot_description/meshes/left_tire.stl" scale="0.001 0.001 0.001"/>-->
      </geometry>
      <origin rpy="1.5707963267948966 0 0" xyz="0 0 0"/>
      <material name="grey"/>
    </visual>
    <collision>
      <geometry>
        <cylinder length="0.02" radius="0.04"/>
      </geometry>
      <origin rpy="1.5707963267948966 0 0" xyz="0 0 0"/>
    </collision>
    <inertial>
      <origin rpy="1.5707963267948966 0 0" xyz="0 0 0"/>
      <mass value="0.2"/>
      <inertia ixx="0.00034666666666666667" ixy="0" ixz="0" iyy="0.00034666666666666667" iyz="0" izz="0.00064"/>
    </inertial>
  </link>
  <joint name="base_joint" type="fixed">
    <parent link="base_footprint"/>
    <child link="base_link"/>
    <origin rpy="0 0 0" xyz="0 0 0.04"/>
  </joint>
  <joint name="lower_right_wheel_joint" type="continuous">
    <parent link="base_link"/>
    <child link="lower_right_wheel_link"/>
    <origin rpy="0 0 0" xyz="-0.065 -0.08499999999999999 0"/>
    <axis xyz="0 1 0"/>
  </joint>
  <joint name="lower_left_wheel_joint" type="continuous">
    <parent link="base_link"/>
    <child link="lower_left_wheel_link"/>
    <origin rpy="0 0 0" xyz="-0.065 0.08499999999999999 0"/>
    <axis xyz="0 1 0"/>
  </joint>
  <joint name="upper_right_wheel_joint" type="continuous">
    <parent link="base_link"/>
    <child link="upper_right_wheel_link"/>
    <origin rpy="0 0 0" xyz="0.065 -0.08499999999999999 0"/>
    <axis xyz="0 1 0"/>
  </joint>
  <joint name="upper_left_wheel_joint" type="continuous">
    <parent link="base_link"/>
    <child link="upper_left_wheel_link"/>
    <origin rpy="0 0 0" xyz="0.065 0.08499999999999999 0"/>
    <axis xyz="0 1 0"/>
  </joint>
  <!-- low friction with base and high friction with wheels -->
  <gazebo reference="base_link">
    <material>Gazebo/Yellow</material>
    <mu1>0.005</mu1>
    <mu2>0.005</mu2>
  </gazebo>
  <gazebo reference="lower_right_wheel_link">
    <material>Gazebo/Grey</material>
    <mu1>0.4</mu1>
    <mu2>0.2</mu2>
    <!--<kp>1000</kp>
        <ki>100</ki>
        <kd>1</kd>
        <minDepth>0.001</minDepth>
        <maxVel>0.5</maxVel>
        <fdir1>1 0 0</fdir1>-->
  </gazebo>
  <gazebo reference="lower_left_wheel_link">
    <material>Gazebo/Grey</material>
    <mu1>0.4</mu1>
    <mu2>0.2</mu2>
    <!--<kp>1000</kp>
        <ki>100</ki>
        <kd>1</kd>
        <minDepth>0.001</minDepth>
        <maxVel>0.5</maxVel>
        <fdir1>1 0 0</fdir1>-->
  </gazebo>
  <gazebo reference="upper_right_wheel_link">
    <material>Gazebo/Grey</material>
    <mu1>0.4</mu1>
    <mu2>0.2</mu2>
    <!--<kp>1000</kp>
        <ki>100</ki>
        <kd>1</kd>
        <minDepth>0.001</minDepth>
        <maxVel>0.5</maxVel>
        <fdir1>1 0 0</fdir1>-->
  </gazebo>
  <gazebo reference="upper_left_wheel_link">
    <material>Gazebo/Grey</material>
    <mu1>0.4</mu1>
    <mu2>0.2</mu2>
    <!--<kp>1000</kp>
        <ki>100</ki>
        <kd>1</kd>
        <minDepth>0.001</minDepth>
        <maxVel>0.5</maxVel>
        <fdir1>1 0 0</fdir1>-->
  </gazebo>
  <gazebo>
    <plugin filename="libgazebo_ros_planar_move.so" name="mecanum_controller">
      <command_topic>cmd_vel</command_topic>
      <odometry_topic>odom</odometry_topic>
      <odometry_frame>odom</odometry_frame>
      <odometry_rate>20.0</odometry_rate>
      <robot_base_frame>base_footprint</robot_base_frame>
      <publish_odom>true</publish_odom>
      <publish_odom_tf>true</publish_odom_tf>
      <wheel_radius>0.04</wheel_radius>
      <base_length>0.65</base_length>
      <base_width>0.65</base_width>
      <publish_wheel_tf>true</publish_wheel_tf>
      <front_left_joint>upper_left_wheel_joint</front_left_joint>
      <front_right_joint>upper_right_wheel_joint</front_right_joint>
      <rear_left_joint>lower_left_wheel_joint</rear_left_joint>
      <rear_right_joint>lower_right_wheel_joint</rear_right_joint>
      <wheel_max_speed> 20.0 </wheel_max_speed>
      <wheel_acceleration> 10.0</wheel_acceleration>
      <joint_config>1 1 1 1</joint_config>
    </plugin>
  </gazebo>
  <link name="camera_link">
    <visual>
      <geometry>
        <box size="0.01 0.1 0.05"/>
      </geometry>
      <material name="grey"/>
    </visual>
    <collision>
      <geometry>
        <box size="0.01 0.1 0.05"/>
      </geometry>
    </collision>
    <inertial>
      <origin rpy="0 0 0" xyz="0 0 0"/>
      <mass value="0.1"/>
      <inertia ixx="2.166666666666667e-05" ixy="0" ixz="0" iyy="8.416666666666668e-05" iyz="0" izz="0.00010416666666666669"/>
    </inertial>
  </link>
  <joint name="base_camera_joint" type="fixed">
    <parent link="base_link"/>
    <child link="camera_link"/>
    <origin rpy="0 0 0" xyz="0.135 0 0.04"/>
  </joint>
  <link name="camera_link_optical">
    </link>
  <joint name="camera_optical_joint" type="fixed">
    <!-- these values have to be these values otherwise the gazebo camera
            image won't be aligned properly with the frame it is supposedly
            originating from -->
    <origin rpy="-1.5707963267948966 0 -1.5707963267948966" xyz="0 0 0"/>
    <parent link="camera_link"/>
    <child link="camera_link_optical"/>
  </joint>
  <gazebo reference="camera_link">
    <material>Gazebo/Red</material>
    <sensor name="camera_sensor" type="camera">
      <pose>0 0 0 0 0 0</pose>
      <visualize>false</visualize>
      <update_rate>10.0</update_rate>
      <plugin filename="libgazebo_ros_camera.so" name="camera_controller">
        <frame_name>camera_link_optical</frame_name>
      </plugin>
    </sensor>
  </gazebo>
  <link name="base_scan">
    <visual>
      <geometry>
        <cylinder length="0.02" radius="0.05"/>
      </geometry>
      <material name="grey"/>
    </visual>
    <collision>
      <geometry>
        <cylinder length="0.02" radius="0.05"/>
      </geometry>
    </collision>
    <inertial>
      <origin rpy="0 0 0" xyz="0 0 0"/>
      <mass value="0.1"/>
      <inertia ixx="0.00026333333333333336" ixy="0" ixz="0" iyy="0.00026333333333333336" iyz="0" izz="0.0005000000000000001"/>
    </inertial>
  </link>
  <joint name="base_scan_joint" type="fixed">
    <parent link="base_link"/>
    <child link="base_scan"/>
    <origin rpy="0 0 3.14" xyz="0 0 0.13"/>
  </joint>
  <gazebo reference="base_scan">
    <sensor name="lidar" type="ray">
      <pose>0.215 0 0.215 0 0 0</pose>
      <always_on>true</always_on>
      <visualize>false</visualize>
      <update_rate>5</update_rate>
      <ray>
        <scan>
          <horizontal>
            <samples>720</samples>
            <resolution>1.00000</resolution>
            <min_angle>0.000000</min_angle>
            <max_angle>6.280000</max_angle>
          </horizontal>
        </scan>
        <range>
          <min>0.120000</min>
          <max>3.5</max>
          <resolution>0.015000</resolution>
        </range>
        <noise>
          <type>gaussian</type>
          <mean>0.0</mean>
          <stddev>0.01</stddev>
        </noise>
      </ray>
      <plugin filename="libgazebo_ros_ray_sensor.so" name="scan">
        <ros>
          <remapping>~/out:=scan</remapping>
        </ros>
        <output_type>sensor_msgs/LaserScan</output_type>
        <frame_name>base_scan</frame_name>
      </plugin>
    </sensor>
  </gazebo>
</robot>
